<?xml version="1.0"?>
<!-- Auto-generated by HoloScript URDFCompiler -->
<!-- Source: composition "TwoDoFRobotArm" -->

<robot name="HoloScriptTwoDoFArm">
  <!-- Materials -->
  <material name="default">
    <color rgba="0.8 0.8 0.8 1.0"/>
  </material>
  
  <link name="base_link">
    <inertial>
      <mass value="0.001"/>
      <inertia ixx="0.001000" ixy="0" ixz="0" iyy="0.001000" iyz="0" izz="0.001000"/>
    </inertial>
  </link>
  
  <link name="base">
    <visual>
      <origin xyz="0 0 0.05" rpy="0.000000 0.000000 0.000000"/>
      <geometry>
        <cylinder radius="0.075" length="0.15"/>
      </geometry>
      <material name="default"/>
    </visual>
    <collision>
      <origin xyz="0 0 0.05" rpy="0.000000 0.000000 0.000000"/>
      <geometry>
        <cylinder radius="0.075" length="0.15"/>
      </geometry>
    </collision>
    <inertial>
      <mass value="10"/>
      <inertia ixx="0.032812" ixy="0" ixz="0" iyy="0.032812" iyz="0" izz="0.028125"/>
    </inertial>
  </link>
  
  <link name="shoulderjoint">
    <visual>
      <origin xyz="0 0 0.1" rpy="0.000000 0.000000 0.000000"/>
      <geometry>
        <cylinder radius="0.025" length="0.05"/>
      </geometry>
      <material name="default"/>
    </visual>
    <collision>
      <origin xyz="0 0 0.1" rpy="0.000000 0.000000 0.000000"/>
      <geometry>
        <cylinder radius="0.025" length="0.05"/>
      </geometry>
    </collision>
    <inertial>
      <mass value="0.5"/>
      <inertia ixx="0.000182" ixy="0" ixz="0" iyy="0.000182" iyz="0" izz="0.000156"/>
    </inertial>
  </link>
  
  <link name="upperarm">
    <visual>
      <origin xyz="0.2 0 0.1" rpy="0.000000 0.000000 0.000000"/>
      <geometry>
        <box size="0.4 0.4 0.4"/>
      </geometry>
      <material name="default"/>
    </visual>
    <collision>
      <origin xyz="0.2 0 0.1" rpy="0.000000 0.000000 0.000000"/>
      <geometry>
        <box size="0.4 0.4 0.4"/>
      </geometry>
    </collision>
    <inertial>
      <mass value="2"/>
      <inertia ixx="0.053333" ixy="0" ixz="0" iyy="0.053333" iyz="0" izz="0.053333"/>
    </inertial>
  </link>
  
  <link name="elbowjoint">
    <visual>
      <origin xyz="0.4 0 0.1" rpy="0.000000 0.000000 0.000000"/>
      <geometry>
        <cylinder radius="0.02" length="0.04"/>
      </geometry>
      <material name="default"/>
    </visual>
    <collision>
      <origin xyz="0.4 0 0.1" rpy="0.000000 0.000000 0.000000"/>
      <geometry>
        <cylinder radius="0.02" length="0.04"/>
      </geometry>
    </collision>
    <inertial>
      <mass value="0.3"/>
      <inertia ixx="0.000070" ixy="0" ixz="0" iyy="0.000070" iyz="0" izz="0.000060"/>
    </inertial>
  </link>
  
  <link name="forearm">
    <visual>
      <origin xyz="0.55 0 0.1" rpy="0.000000 0.000000 0.000000"/>
      <geometry>
        <box size="0.3 0.3 0.3"/>
      </geometry>
      <material name="default"/>
    </visual>
    <collision>
      <origin xyz="0.55 0 0.1" rpy="0.000000 0.000000 0.000000"/>
      <geometry>
        <box size="0.3 0.3 0.3"/>
      </geometry>
    </collision>
    <inertial>
      <mass value="1"/>
      <inertia ixx="0.015000" ixy="0" ixz="0" iyy="0.015000" iyz="0" izz="0.015000"/>
    </inertial>
  </link>
  
  <link name="endeffector">
    <visual>
      <origin xyz="0.7 0 0.1" rpy="0.000000 0.000000 0.000000"/>
      <geometry>
        <sphere radius="0.025"/>
      </geometry>
      <material name="default"/>
    </visual>
    <collision>
      <origin xyz="0.7 0 0.1" rpy="0.000000 0.000000 0.000000"/>
      <geometry>
        <sphere radius="0.025"/>
      </geometry>
    </collision>
    <inertial>
      <mass value="0.2"/>
      <inertia ixx="0.000050" ixy="0" ixz="0" iyy="0.000050" iyz="0" izz="0.000050"/>
    </inertial>
  </link>
  
  <joint name="base_link_to_base_joint" type="fixed">
    <parent link="base_link"/>
    <child link="base"/>
    <origin xyz="0 0 0.05" rpy="0.000000 0.000000 0.000000"/>
  </joint>
  
  <joint name="base_to_shoulderjoint_joint" type="revolute">
    <parent link="base"/>
    <child link="shoulderjoint"/>
    <origin xyz="0 0 0.1" rpy="0.000000 0.000000 0.000000"/>
    <axis xyz="0 0 1"/>
    <limit lower="-3.141592653589793" upper="3.141592653589793" effort="100" velocity="1"/>
    <dynamics damping="0.1" friction="0"/>
  </joint>
  
  <joint name="base_link_to_upperarm_joint" type="fixed">
    <parent link="base_link"/>
    <child link="upperarm"/>
    <origin xyz="0.2 0 0.1" rpy="0.000000 0.000000 0.000000"/>
  </joint>
  
  <joint name="upperarm_to_elbowjoint_joint" type="revolute">
    <parent link="upperarm"/>
    <child link="elbowjoint"/>
    <origin xyz="0.4 0 0.1" rpy="0.000000 0.000000 0.000000"/>
    <axis xyz="0 1 0"/>
    <limit lower="-2.356194490192345" upper="2.356194490192345" effort="50" velocity="1"/>
    <dynamics damping="0.1" friction="0"/>
  </joint>
  
  <joint name="base_link_to_forearm_joint" type="fixed">
    <parent link="base_link"/>
    <child link="forearm"/>
    <origin xyz="0.55 0 0.1" rpy="0.000000 0.000000 0.000000"/>
  </joint>
  
  <joint name="base_link_to_endeffector_joint" type="fixed">
    <parent link="base_link"/>
    <child link="endeffector"/>
    <origin xyz="0.7 0 0.1" rpy="0.000000 0.000000 0.000000"/>
  </joint>
  
  
  <!-- HoloScript Extensions -->
  <!-- Original composition: "TwoDoFRobotArm" -->
</robot>